2024-08-20T13:57:56 {"block_run_id": 3, "block_uuid": "chromatic_dimension", "pipeline_run_id": 1, "pipeline_schedule_id": 3, "pipeline_uuid": "resonant_kinesis", "hostname": "4d5382912dd9", "block_type": "data_exporter", "level": "INFO", "message": "Start executing block with BlockExecutor.", "timestamp": 1724162276.476901, "uuid": "05cf6860d5f24c86a77247c445c2e8c1"}
2024-08-20T13:57:57 {"block_run_id": 3, "block_uuid": "chromatic_dimension", "pipeline_run_id": 1, "pipeline_schedule_id": 3, "pipeline_uuid": "resonant_kinesis", "hostname": "4d5382912dd9", "block_type": "data_exporter", "level": "INFO", "message": "Index name:", "timestamp": 1724162277.751297, "uuid": "52fee9b572d5434f9bc379d3d28e3f61"}
2024-08-20T13:57:57 {"block_run_id": 3, "block_uuid": "chromatic_dimension", "pipeline_run_id": 1, "pipeline_schedule_id": 3, "pipeline_uuid": "resonant_kinesis", "hostname": "4d5382912dd9", "block_type": "data_exporter", "level": "INFO", "message": "documents_20240820_5757", "timestamp": 1724162277.762169, "uuid": "9715626c5c51464d820135150f56e568"}
2024-08-20T13:57:58 {"block_run_id": 3, "block_uuid": "chromatic_dimension", "pipeline_run_id": 1, "pipeline_schedule_id": 3, "pipeline_uuid": "resonant_kinesis", "hostname": "4d5382912dd9", "block_type": "data_exporter", "level": "INFO", "message": "Connecting to Elasticsearch at http://elasticsearch:9200", "timestamp": 1724162278.140794, "uuid": "3f7367bf4b684d559fcbf4d16b9637b0"}
2024-08-20T13:58:00 {"block_run_id": 3, "block_uuid": "chromatic_dimension", "pipeline_run_id": 1, "pipeline_schedule_id": 3, "pipeline_uuid": "resonant_kinesis", "hostname": "4d5382912dd9", "block_type": "data_exporter", "level": "WARNING", "message": "Exception thrown when attempting to run <function BlockExecutor.execute.<locals>.__execute_with_retry at 0x75f534ae6950>, attempt 1 of 1", "timestamp": 1724162280.362467, "uuid": "f2716f6fc4054ab8aadeeb3442d7ce73", "error": ["Traceback (most recent call last):\n  File \"/usr/local/lib/python3.10/site-packages/mage_ai/shared/retry.py\", line 38, in retry_func\n    return func(*args, **kwargs)\n  File \"/usr/local/lib/python3.10/site-packages/mage_ai/data_preparation/executors/block_executor.py\", line 621, in __execute_with_retry\n    return self._execute(\n  File \"/usr/local/lib/python3.10/site-packages/mage_ai/data_preparation/executors/block_executor.py\", line 1154, in _execute\n    result = self.block.execute_sync(\n  File \"/usr/local/lib/python3.10/site-packages/mage_ai/data_preparation/models/block/__init__.py\", line 1688, in execute_sync\n    return __execute()\n  File \"/usr/local/lib/python3.10/site-packages/mage_ai/data_preparation/models/block/__init__.py\", line 1665, in __execute\n    raise err\n  File \"/usr/local/lib/python3.10/site-packages/mage_ai/data_preparation/models/block/__init__.py\", line 1567, in __execute\n    output = self.execute_block(\n  File \"/usr/local/lib/python3.10/site-packages/mage_ai/data_preparation/models/block/__init__.py\", line 1912, in execute_block\n    outputs = self._execute_block(\n  File \"/usr/local/lib/python3.10/site-packages/mage_ai/data_preparation/models/block/__init__.py\", line 2075, in _execute_block\n    outputs = self.execute_block_function(\n  File \"/usr/local/lib/python3.10/site-packages/mage_ai/data_preparation/models/block/__init__.py\", line 2186, in execute_block_function\n    output = block_function_updated(*input_vars, **runtime_variables)\n  File \"<string>\", line 67, in elasticsearch\n  File \"/usr/local/lib/python3.10/site-packages/elasticsearch/_sync/client/utils.py\", line 414, in wrapped\n    return api(*args, **kwargs)\n  File \"/usr/local/lib/python3.10/site-packages/elasticsearch/_sync/client/indices.py\", line 517, in create\n    return self.perform_request(  # type: ignore[return-value]\n  File \"/usr/local/lib/python3.10/site-packages/elasticsearch/_sync/client/_base.py\", line 389, in perform_request\n    return self._client.perform_request(\n  File \"/usr/local/lib/python3.10/site-packages/elasticsearch/_sync/client/_base.py\", line 320, in perform_request\n    raise HTTP_EXCEPTIONS.get(meta.status, ApiError)(\nelasticsearch.BadRequestError: BadRequestError(400, 'mapper_parsing_exception', 'No type specified for field [embedding]')\n"], "error_stack": [["  File \"<string>\", line 1, in <module>\n", "  File \"/usr/local/lib/python3.10/multiprocessing/spawn.py\", line 116, in spawn_main\n    exitcode = _main(fd, parent_sentinel)\n", "  File \"/usr/local/lib/python3.10/multiprocessing/spawn.py\", line 129, in _main\n    return self._bootstrap(parent_sentinel)\n", "  File \"/usr/local/lib/python3.10/multiprocessing/process.py\", line 314, in _bootstrap\n    self.run()\n", "  File \"/usr/local/lib/python3.10/site-packages/newrelic/api/background_task.py\", line 117, in wrapper\n    return wrapped(*args, **kwargs)\n", "  File \"/usr/local/lib/python3.10/site-packages/mage_ai/orchestration/queue/process_queue.py\", line 315, in run\n    start_session_and_run(args[1], *args[2], **args[3])\n", "  File \"/usr/local/lib/python3.10/site-packages/mage_ai/orchestration/db/process.py\", line 15, in start_session_and_run\n    results = target(*args)\n", "  File \"/usr/local/lib/python3.10/site-packages/mage_ai/orchestration/pipeline_scheduler_original.py\", line 1233, in run_block\n    return ExecutorFactory.get_block_executor(\n", "  File \"/usr/local/lib/python3.10/site-packages/mage_ai/data_preparation/executors/block_executor.py\", line 647, in execute\n    result = __execute_with_retry()\n", "  File \"/usr/local/lib/python3.10/site-packages/mage_ai/shared/retry.py\", line 46, in retry_func\n    logger.warning(\n", "  File \"/usr/local/lib/python3.10/site-packages/mage_ai/data_preparation/logging/logger.py\", line 39, in warning\n    self.__send_message('warning', message, **kwargs)\n", "  File \"/usr/local/lib/python3.10/site-packages/mage_ai/data_preparation/logging/logger.py\", line 65, in __send_message\n    data['error_stack'] = traceback.format_stack(),\n"]], "error_stacktrace": ["BadRequestError(400, 'mapper_parsing_exception', 'No type specified for field [embedding]')"]}
2024-08-20T13:58:00 {"block_run_id": 3, "block_uuid": "chromatic_dimension", "pipeline_run_id": 1, "pipeline_schedule_id": 3, "pipeline_uuid": "resonant_kinesis", "hostname": "4d5382912dd9", "block_type": "data_exporter", "level": "EXCEPTION", "message": "Failed to execute block chromatic_dimension", "timestamp": 1724162280.401493, "uuid": "b165feb1ce484c40a2c8ec70f23775f2", "error": ["Traceback (most recent call last):\n  File \"/usr/local/lib/python3.10/site-packages/mage_ai/data_preparation/executors/block_executor.py\", line 647, in execute\n    result = __execute_with_retry()\n  File \"/usr/local/lib/python3.10/site-packages/mage_ai/shared/retry.py\", line 54, in retry_func\n    raise e\n  File \"/usr/local/lib/python3.10/site-packages/mage_ai/shared/retry.py\", line 38, in retry_func\n    return func(*args, **kwargs)\n  File \"/usr/local/lib/python3.10/site-packages/mage_ai/data_preparation/executors/block_executor.py\", line 621, in __execute_with_retry\n    return self._execute(\n  File \"/usr/local/lib/python3.10/site-packages/mage_ai/data_preparation/executors/block_executor.py\", line 1154, in _execute\n    result = self.block.execute_sync(\n  File \"/usr/local/lib/python3.10/site-packages/mage_ai/data_preparation/models/block/__init__.py\", line 1688, in execute_sync\n    return __execute()\n  File \"/usr/local/lib/python3.10/site-packages/mage_ai/data_preparation/models/block/__init__.py\", line 1665, in __execute\n    raise err\n  File \"/usr/local/lib/python3.10/site-packages/mage_ai/data_preparation/models/block/__init__.py\", line 1567, in __execute\n    output = self.execute_block(\n  File \"/usr/local/lib/python3.10/site-packages/mage_ai/data_preparation/models/block/__init__.py\", line 1912, in execute_block\n    outputs = self._execute_block(\n  File \"/usr/local/lib/python3.10/site-packages/mage_ai/data_preparation/models/block/__init__.py\", line 2075, in _execute_block\n    outputs = self.execute_block_function(\n  File \"/usr/local/lib/python3.10/site-packages/mage_ai/data_preparation/models/block/__init__.py\", line 2186, in execute_block_function\n    output = block_function_updated(*input_vars, **runtime_variables)\n  File \"<string>\", line 67, in elasticsearch\n  File \"/usr/local/lib/python3.10/site-packages/elasticsearch/_sync/client/utils.py\", line 414, in wrapped\n    return api(*args, **kwargs)\n  File \"/usr/local/lib/python3.10/site-packages/elasticsearch/_sync/client/indices.py\", line 517, in create\n    return self.perform_request(  # type: ignore[return-value]\n  File \"/usr/local/lib/python3.10/site-packages/elasticsearch/_sync/client/_base.py\", line 389, in perform_request\n    return self._client.perform_request(\n  File \"/usr/local/lib/python3.10/site-packages/elasticsearch/_sync/client/_base.py\", line 320, in perform_request\n    raise HTTP_EXCEPTIONS.get(meta.status, ApiError)(\nelasticsearch.BadRequestError: BadRequestError(400, 'mapper_parsing_exception', 'No type specified for field [embedding]')\n"], "error_stack": [["  File \"<string>\", line 1, in <module>\n", "  File \"/usr/local/lib/python3.10/multiprocessing/spawn.py\", line 116, in spawn_main\n    exitcode = _main(fd, parent_sentinel)\n", "  File \"/usr/local/lib/python3.10/multiprocessing/spawn.py\", line 129, in _main\n    return self._bootstrap(parent_sentinel)\n", "  File \"/usr/local/lib/python3.10/multiprocessing/process.py\", line 314, in _bootstrap\n    self.run()\n", "  File \"/usr/local/lib/python3.10/site-packages/newrelic/api/background_task.py\", line 117, in wrapper\n    return wrapped(*args, **kwargs)\n", "  File \"/usr/local/lib/python3.10/site-packages/mage_ai/orchestration/queue/process_queue.py\", line 315, in run\n    start_session_and_run(args[1], *args[2], **args[3])\n", "  File \"/usr/local/lib/python3.10/site-packages/mage_ai/orchestration/db/process.py\", line 15, in start_session_and_run\n    results = target(*args)\n", "  File \"/usr/local/lib/python3.10/site-packages/mage_ai/orchestration/pipeline_scheduler_original.py\", line 1233, in run_block\n    return ExecutorFactory.get_block_executor(\n", "  File \"/usr/local/lib/python3.10/site-packages/mage_ai/data_preparation/executors/block_executor.py\", line 649, in execute\n    self.logger.exception(\n", "  File \"/usr/local/lib/python3.10/site-packages/mage_ai/data_preparation/logging/logger.py\", line 30, in exception\n    self.__send_message('exception', message, **kwargs)\n", "  File \"/usr/local/lib/python3.10/site-packages/mage_ai/data_preparation/logging/logger.py\", line 65, in __send_message\n    data['error_stack'] = traceback.format_stack(),\n"]], "error_stacktrace": ["BadRequestError(400, 'mapper_parsing_exception', 'No type specified for field [embedding]')"]}
Traceback (most recent call last):
  File "/usr/local/lib/python3.10/site-packages/mage_ai/data_preparation/executors/block_executor.py", line 647, in execute
    result = __execute_with_retry()
  File "/usr/local/lib/python3.10/site-packages/mage_ai/shared/retry.py", line 54, in retry_func
    raise e
  File "/usr/local/lib/python3.10/site-packages/mage_ai/shared/retry.py", line 38, in retry_func
    return func(*args, **kwargs)
  File "/usr/local/lib/python3.10/site-packages/mage_ai/data_preparation/executors/block_executor.py", line 621, in __execute_with_retry
    return self._execute(
  File "/usr/local/lib/python3.10/site-packages/mage_ai/data_preparation/executors/block_executor.py", line 1154, in _execute
    result = self.block.execute_sync(
  File "/usr/local/lib/python3.10/site-packages/mage_ai/data_preparation/models/block/__init__.py", line 1688, in execute_sync
    return __execute()
  File "/usr/local/lib/python3.10/site-packages/mage_ai/data_preparation/models/block/__init__.py", line 1665, in __execute
    raise err
  File "/usr/local/lib/python3.10/site-packages/mage_ai/data_preparation/models/block/__init__.py", line 1567, in __execute
    output = self.execute_block(
  File "/usr/local/lib/python3.10/site-packages/mage_ai/data_preparation/models/block/__init__.py", line 1912, in execute_block
    outputs = self._execute_block(
  File "/usr/local/lib/python3.10/site-packages/mage_ai/data_preparation/models/block/__init__.py", line 2075, in _execute_block
    outputs = self.execute_block_function(
  File "/usr/local/lib/python3.10/site-packages/mage_ai/data_preparation/models/block/__init__.py", line 2186, in execute_block_function
    output = block_function_updated(*input_vars, **runtime_variables)
  File "<string>", line 67, in elasticsearch
  File "/usr/local/lib/python3.10/site-packages/elasticsearch/_sync/client/utils.py", line 414, in wrapped
    return api(*args, **kwargs)
  File "/usr/local/lib/python3.10/site-packages/elasticsearch/_sync/client/indices.py", line 517, in create
    return self.perform_request(  # type: ignore[return-value]
  File "/usr/local/lib/python3.10/site-packages/elasticsearch/_sync/client/_base.py", line 389, in perform_request
    return self._client.perform_request(
  File "/usr/local/lib/python3.10/site-packages/elasticsearch/_sync/client/_base.py", line 320, in perform_request
    raise HTTP_EXCEPTIONS.get(meta.status, ApiError)(
elasticsearch.BadRequestError: BadRequestError(400, 'mapper_parsing_exception', 'No type specified for field [embedding]')
