2024-08-20T13:57:43 {"cpu": 0.447265625, "cpu_total": 4, "cpu_usage": 0.11181640625, "memory": 12564.0, "memory_total": 15981.0, "memory_usage": 0.7861835930167074, "pipeline_run_id": 1, "pipeline_schedule_id": 3, "pipeline_uuid": "resonant_kinesis", "hostname": "4d5382912dd9", "level": "INFO", "message": "Pipeline resonant_kinesis for run 1 in schedule 3 is alive.", "timestamp": 1724162263.631639, "uuid": "8204c01a63884d918ac85928c16e1995"}
2024-08-20T13:57:43 {"cpu": 0.447265625, "cpu_total": 4, "cpu_usage": 0.11181640625, "memory": 12589.0, "memory_total": 15981.0, "memory_usage": 0.7877479506914461, "pipeline_run_id": 1, "pipeline_schedule_id": 3, "pipeline_uuid": "resonant_kinesis", "hostname": "4d5382912dd9", "level": "INFO", "message": "Pipeline resonant_kinesis for run 1 in schedule 3 is alive.", "timestamp": 1724162263.927356, "uuid": "613b36ed440443caa3d59b105cf027f9"}
2024-08-20T13:57:54 {"cpu": 0.5927734375, "cpu_total": 4, "cpu_usage": 0.148193359375, "memory": 13216.0, "memory_total": 15981.0, "memory_usage": 0.826982041173894, "pipeline_run_id": 1, "pipeline_schedule_id": 3, "pipeline_uuid": "resonant_kinesis", "hostname": "4d5382912dd9", "level": "INFO", "message": "Pipeline resonant_kinesis for run 1 in schedule 3 is alive.", "timestamp": 1724162274.062936, "uuid": "3e013edc46f04366bd450e373c420a9d"}
2024-08-20T13:57:56 {"block_run_id": 3, "block_uuid": "chromatic_dimension", "pipeline_run_id": 1, "pipeline_schedule_id": 3, "pipeline_uuid": "resonant_kinesis", "hostname": "4d5382912dd9", "level": "INFO", "message": "Execute PipelineRun 1, BlockRun 3: pipeline resonant_kinesis block chromatic_dimension", "timestamp": 1724162276.409079, "uuid": "3510676148cf461c98e4ef3c31d7fa8c"}
2024-08-20T13:58:01 {"block_run_id": 3, "block_uuid": "chromatic_dimension", "pipeline_run_id": 1, "pipeline_schedule_id": 3, "pipeline_uuid": "resonant_kinesis", "hostname": "4d5382912dd9", "level": "EXCEPTION", "message": "BlockRun 3 (block_uuid: chromatic_dimension) failed.", "timestamp": 1724162281.661788, "uuid": "4c8baf9a6a1f434a9fe9d017869d8fa3", "error": ["Traceback (most recent call last):\n  File \"/usr/local/lib/python3.10/site-packages/mage_ai/data_preparation/executors/block_executor.py\", line 647, in execute\n    result = __execute_with_retry()\n  File \"/usr/local/lib/python3.10/site-packages/mage_ai/shared/retry.py\", line 54, in retry_func\n    raise e\n  File \"/usr/local/lib/python3.10/site-packages/mage_ai/shared/retry.py\", line 38, in retry_func\n    return func(*args, **kwargs)\n  File \"/usr/local/lib/python3.10/site-packages/mage_ai/data_preparation/executors/block_executor.py\", line 621, in __execute_with_retry\n    return self._execute(\n  File \"/usr/local/lib/python3.10/site-packages/mage_ai/data_preparation/executors/block_executor.py\", line 1154, in _execute\n    result = self.block.execute_sync(\n  File \"/usr/local/lib/python3.10/site-packages/mage_ai/data_preparation/models/block/__init__.py\", line 1688, in execute_sync\n    return __execute()\n  File \"/usr/local/lib/python3.10/site-packages/mage_ai/data_preparation/models/block/__init__.py\", line 1665, in __execute\n    raise err\n  File \"/usr/local/lib/python3.10/site-packages/mage_ai/data_preparation/models/block/__init__.py\", line 1567, in __execute\n    output = self.execute_block(\n  File \"/usr/local/lib/python3.10/site-packages/mage_ai/data_preparation/models/block/__init__.py\", line 1912, in execute_block\n    outputs = self._execute_block(\n  File \"/usr/local/lib/python3.10/site-packages/mage_ai/data_preparation/models/block/__init__.py\", line 2075, in _execute_block\n    outputs = self.execute_block_function(\n  File \"/usr/local/lib/python3.10/site-packages/mage_ai/data_preparation/models/block/__init__.py\", line 2186, in execute_block_function\n    output = block_function_updated(*input_vars, **runtime_variables)\n  File \"<string>\", line 67, in elasticsearch\n  File \"/usr/local/lib/python3.10/site-packages/elasticsearch/_sync/client/utils.py\", line 414, in wrapped\n    return api(*args, **kwargs)\n  File \"/usr/local/lib/python3.10/site-packages/elasticsearch/_sync/client/indices.py\", line 517, in create\n    return self.perform_request(  # type: ignore[return-value]\n  File \"/usr/local/lib/python3.10/site-packages/elasticsearch/_sync/client/_base.py\", line 389, in perform_request\n    return self._client.perform_request(\n  File \"/usr/local/lib/python3.10/site-packages/elasticsearch/_sync/client/_base.py\", line 320, in perform_request\n    raise HTTP_EXCEPTIONS.get(meta.status, ApiError)(\nelasticsearch.BadRequestError: BadRequestError(400, 'mapper_parsing_exception', 'No type specified for field [embedding]')\n"], "error_stack": [["  File \"<string>\", line 1, in <module>\n", "  File \"/usr/local/lib/python3.10/multiprocessing/spawn.py\", line 116, in spawn_main\n    exitcode = _main(fd, parent_sentinel)\n", "  File \"/usr/local/lib/python3.10/multiprocessing/spawn.py\", line 129, in _main\n    return self._bootstrap(parent_sentinel)\n", "  File \"/usr/local/lib/python3.10/multiprocessing/process.py\", line 314, in _bootstrap\n    self.run()\n", "  File \"/usr/local/lib/python3.10/site-packages/newrelic/api/background_task.py\", line 117, in wrapper\n    return wrapped(*args, **kwargs)\n", "  File \"/usr/local/lib/python3.10/site-packages/mage_ai/orchestration/queue/process_queue.py\", line 315, in run\n    start_session_and_run(args[1], *args[2], **args[3])\n", "  File \"/usr/local/lib/python3.10/site-packages/mage_ai/orchestration/db/process.py\", line 15, in start_session_and_run\n    results = target(*args)\n", "  File \"/usr/local/lib/python3.10/site-packages/mage_ai/orchestration/pipeline_scheduler_original.py\", line 1233, in run_block\n    return ExecutorFactory.get_block_executor(\n", "  File \"/usr/local/lib/python3.10/site-packages/mage_ai/data_preparation/executors/block_executor.py\", line 682, in execute\n    on_failure(\n", "  File \"/usr/local/lib/python3.10/site-packages/mage_ai/orchestration/db/__init__.py\", line 158, in func_with_rollback\n    return func(*args, **kwargs)\n", "  File \"/usr/local/lib/python3.10/site-packages/mage_ai/orchestration/pipeline_scheduler_original.py\", line 466, in on_block_failure\n    self.logger.exception(\n", "  File \"/usr/local/lib/python3.10/site-packages/mage_ai/data_preparation/logging/logger.py\", line 30, in exception\n    self.__send_message('exception', message, **kwargs)\n", "  File \"/usr/local/lib/python3.10/site-packages/mage_ai/data_preparation/logging/logger.py\", line 65, in __send_message\n    data['error_stack'] = traceback.format_stack(),\n"]], "error_stacktrace": ["BadRequestError(400, 'mapper_parsing_exception', 'No type specified for field [embedding]')"]}
Traceback (most recent call last):
  File "/usr/local/lib/python3.10/site-packages/mage_ai/data_preparation/executors/block_executor.py", line 647, in execute
    result = __execute_with_retry()
  File "/usr/local/lib/python3.10/site-packages/mage_ai/shared/retry.py", line 54, in retry_func
    raise e
  File "/usr/local/lib/python3.10/site-packages/mage_ai/shared/retry.py", line 38, in retry_func
    return func(*args, **kwargs)
  File "/usr/local/lib/python3.10/site-packages/mage_ai/data_preparation/executors/block_executor.py", line 621, in __execute_with_retry
    return self._execute(
  File "/usr/local/lib/python3.10/site-packages/mage_ai/data_preparation/executors/block_executor.py", line 1154, in _execute
    result = self.block.execute_sync(
  File "/usr/local/lib/python3.10/site-packages/mage_ai/data_preparation/models/block/__init__.py", line 1688, in execute_sync
    return __execute()
  File "/usr/local/lib/python3.10/site-packages/mage_ai/data_preparation/models/block/__init__.py", line 1665, in __execute
    raise err
  File "/usr/local/lib/python3.10/site-packages/mage_ai/data_preparation/models/block/__init__.py", line 1567, in __execute
    output = self.execute_block(
  File "/usr/local/lib/python3.10/site-packages/mage_ai/data_preparation/models/block/__init__.py", line 1912, in execute_block
    outputs = self._execute_block(
  File "/usr/local/lib/python3.10/site-packages/mage_ai/data_preparation/models/block/__init__.py", line 2075, in _execute_block
    outputs = self.execute_block_function(
  File "/usr/local/lib/python3.10/site-packages/mage_ai/data_preparation/models/block/__init__.py", line 2186, in execute_block_function
    output = block_function_updated(*input_vars, **runtime_variables)
  File "<string>", line 67, in elasticsearch
  File "/usr/local/lib/python3.10/site-packages/elasticsearch/_sync/client/utils.py", line 414, in wrapped
    return api(*args, **kwargs)
  File "/usr/local/lib/python3.10/site-packages/elasticsearch/_sync/client/indices.py", line 517, in create
    return self.perform_request(  # type: ignore[return-value]
  File "/usr/local/lib/python3.10/site-packages/elasticsearch/_sync/client/_base.py", line 389, in perform_request
    return self._client.perform_request(
  File "/usr/local/lib/python3.10/site-packages/elasticsearch/_sync/client/_base.py", line 320, in perform_request
    raise HTTP_EXCEPTIONS.get(meta.status, ApiError)(
elasticsearch.BadRequestError: BadRequestError(400, 'mapper_parsing_exception', 'No type specified for field [embedding]')
2024-08-20T13:58:03 {"cpu": 0.73681640625, "cpu_total": 4, "cpu_usage": 0.1842041015625, "memory": 13368.0, "memory_total": 15981.0, "memory_usage": 0.8364933358363056, "pipeline_run_id": 1, "pipeline_schedule_id": 3, "pipeline_uuid": "resonant_kinesis", "hostname": "4d5382912dd9", "level": "INFO", "message": "Pipeline resonant_kinesis for run 1 in schedule 3 is alive.", "timestamp": 1724162283.291448, "uuid": "e347bae34f5a41c180be8e02811d95c7"}
